<mujoco model="single_arm">
  <option timestep="0.001" gravity="0 0 -9.81"/>
  
  <asset>
    <texture name="grid" type="2d" builtin="checker" width="512" height="512" rgb1=".1 .2 .3" rgb2=".2 .3 .4"/>
    <material name="grid" texture="grid" texrepeat="1 1" texuniform="true" reflectance=".2"/>
    <material name="base_mat" rgba="0.3 0.3 0.3 1"/>
    <material name="link1_mat" rgba="0.6 0.3 0.1 1"/>
    <material name="link2_mat" rgba="0.1 0.5 0.8 1"/>
    <material name="link3_mat" rgba="0.8 0.2 0.2 1"/>
  </asset>
  
  <worldbody>
    <geom name="floor" type="plane" size="2 2 0.1" material="grid"/>
    <light directional="true" pos="0 0 3" dir="0 0 -1"/>
    
    <!-- 基座 base_link：直径0.15m(半径0.075m)，高度0.06m -->
    <body name="base_link" pos="0 0 0.03">
      <geom name="base_geom" type="cylinder" size="0.075 0.03" material="base_mat"/>
      
      <!-- link1：竖直圆柱，直径0.03m(半径0.015m)，高0.08m -->
      <!-- 相对base_link向上移动0.03+0.04=0.07m -->
      <body name="link1" pos="0 0 0.07">
        <joint name="joint1" type="hinge" axis="0 0 1" limited="false" damping="0.1"/>
        <geom name="link1_geom" type="cylinder" size="0.015 0.04" material="link1_mat"/>
        <inertial pos="0 0 0" mass="0.5" diaginertia="0.001 0.001 0.0001"/>
        
        <!-- link2：水平圆柱，直径0.03m(半径0.015m)，长0.3m -->
        <!-- 单侧放置，一端与link1上表面边缘重合 -->
        <!-- link1上表面在相对位置z=0.04，link2中心在x=0.15处 -->
        <body name="link2" pos="0.15 0 0.04">
          <geom name="link2_geom" type="cylinder" size="0.015 0.15" 
                quat="0.707107 0 0.707107 0" material="link2_mat"/>
          <inertial pos="0 0 0" mass="0.6" diaginertia="0.006 0.006 0.0001"/>
          
          <!-- link3：水平圆柱体，直径0.07m(半径0.035m)，长0.05m -->
          <!-- 位于link2中心（质心位置），与link2共轴-->
          <body name="link3" pos="0 0 0">
            <geom name="link3_geom" type="cylinder" size="0.035 0.025" 
                  quat="0.707107 0 0.707107 0" material="link3_mat"/>
            <inertial pos="0 0 0" mass="0.4" diaginertia="0.0008 0.0008 0.0002"/>
          </body>
        </body>
      </body>
    </body>
  </worldbody>
  
  <actuator>
    <motor name="motor1" joint="joint1" gear="1" ctrllimited="true" ctrlrange="-10 10"/>
  </actuator>
  
</mujoco>

